Workbook
Name rngAlcohol: '2_Clean_Data'!$L$2:INDEX('2_Clean_Data'!$L:$L,COUNTA('2_Clean_Data'!$A:$A))
Name rngCitric: '2_Clean_Data'!$D$2:INDEX('2_Clean_Data'!$D:$D,COUNTA('2_Clean_Data'!$A:$A))
Name rngData: '2_Clean_Data'!$B$2:INDEX('2_Clean_Data'!$M:$M,COUNTA('2_Clean_Data'!$A:$A))
Name rngPH: '2_Clean_Data'!$J$2:INDEX('2_Clean_Data'!$J:$J,COUNTA('2_Clean_Data'!$A:$A))
Name rngQuality: '2_Clean_Data'!$M$2:INDEX('2_Clean_Data'!$M:$M,COUNTA('2_Clean_Data'!$A:$A))
Name rngSulphates: '2_Clean_Data'!$K$2:INDEX('2_Clean_Data'!$K:$K,COUNTA('2_Clean_Data'!$A:$A))
Name rngVolatile: '2_Clean_Data'!$C$2:INDEX('2_Clean_Data'!$C:$C,COUNTA('2_Clean_Data'!$A:$A))
Name selAhi: '6_Dashboard'!$Q$6
Name selAlo: '6_Dashboard'!$Q$5
Name selQmax: '6_Dashboard'!$Q$4
Name selQmin: '6_Dashboard'!$Q$3

Sheet 1_Raw_Data
A1: fixed acidity | B1: volatile acidity | C1: citric acid | D1: residual sugar | E1: chlorides | F1: free sulfur dioxide | G1: total sulfur dioxide | H1: density | I1: pH | J1: sulphates | K1: alcohol | L1: quality
A2: 7.4 | B2: 0.7 | C2: 0 | D2: 1.9 | E2: 0.076 | F2: 11 | G2: 34 | H2: 0.9978 | I2: 3.51 | J2: 0.56 | K2: 9.4 | L2: 5
A3: 7.8 | B3: 0.88 | C3: 0 | D3: 2.6 | E3: 0.098 | F3: 25 | G3: 67 | H3: 0.9968 | I3: 3.2 | J3: 0.68 | K3: 9.8 | L3: 5
A4: 7.8 | B4: 0.76 | C4: 0.04 | D4: 2.3 | E4: 0.092 | F4: 15 | G4: 54 | H4: 0.997 | I4: 3.26 | J4: 0.65 | K4: 9.8 | L4: 5
A5: 11.2 | B5: 0.28 | C5: 0.56 | D5: 1.9 | E5: 0.075 | F5: 17 | G5: 60 | H5: 0.998 | I5: 3.16 | J5: 0.58 | K5: 9.8 | L5: 6
A6: 7.4 | B6: 0.7 | C6: 0 | D6: 1.9 | E6: 0.076 | F6: 11 | G6: 34 | H6: 0.9978 | I6: 3.51 | J6: 0.56 | K6: 9.4 | L6: 5
A7: 7.4 | B7: 0.66 | C7: 0 | D7: 1.8 | E7: 0.075 | F7: 13 | G7: 40 | H7: 0.9978 | I7: 3.51 | J7: 0.56 | K7: 9.4 | L7: 5
A8: 7.9 | B8: 0.6 | C8: 0.06 | D8: 1.6 | E8: 0.069 | F8: 15 | G8: 59 | H8: 0.9964 | I8: 3.3 | J8: 0.46 | K8: 9.4 | L8: 5
A9: 7.3 | B9: 0.65 | C9: 0 | D9: 1.2 | E9: 0.065 | F9: 15 | G9: 21 | H9: 0.9946 | I9: 3.39 | J9: 0.47 | K9: 10 | L9: 7
A10: 7.8 | B10: 0.58 | C10: 0.02 | D10: 2 | E10: 0.073 | F10: 9 | G10: 18 | H10: 0.9968 | I10: 3.36 | J10: 0.57 | K10: 9.5 | L10: 7
A11: 7.5 | B11: 0.5 | C11: 0.36 | D11: 6.1 | E11: 0.071 | F11: 17 | G11: 102 | H11: 0.9978 | I11: 3.35 | J11: 0.8 | K11: 10.5 | L11: 5
A12: 6.7 | B12: 0.58 | C12: 0.08 | D12: 1.8 | E12: 0.097 | F12: 15 | G12: 65 | H12: 0.9959 | I12: 3.28 | J12: 0.54 | K12: 9.2 | L12: 5
A13: 7.5 | B13: 0.5 | C13: 0.36 | D13: 6.1 | E13: 0.071 | F13: 17 | G13: 102 | H13: 0.9978 | I13: 3.35 | J13: 0.8 | K13: 10.5 | L13: 5
... A1600: 6 | B1600: 0.31 | C1600: 0.47 | D1600: 3.6 | E1600: 0.067 | F1600: 18 | G1600: 42 | H1600: 0.99549 | I1600: 3.39 | J1600: 0.66 | K1600: 11 | L1600: 6

Sheet 2_Clean_Data
A1: Wine_ID | B1: Fixed_Acidity | C1: Volatile_Acidity | D1: Citric_Acid | E1: Residual_Sugar | F1: Chlorides | G1: Free_Sulfur_Dioxide | H1: Total_Sulfur_Dioxide | I1: Density | J1: pH | K1: Sulphates | L1: Alcohol | M1: Quality
A2: 1 | B2: 7.4 | C2: 0.7 | D2: 0 | E2: 1.9 | F2: 0.076 | G2: 11 | H2: 34 | I2: 0.9978 | J2: 3.51 | K2: 0.56 | L2: 9.4 | M2: 5
A3: 2 | B3: 7.8 | C3: 0.88 | D3: 0 | E3: 2.6 | F3: 0.098 | G3: 25 | H3: 67 | I3: 0.9968 | J3: 3.2 | K3: 0.68 | L3: 9.8 | M3: 5
A4: 3 | B4: 7.8 | C4: 0.76 | D4: 0.04 | E4: 2.3 | F4: 0.092 | G4: 15 | H4: 54 | I4: 0.997 | J4: 3.26 | K4: 0.65 | L4: 9.8 | M4: 5
A5: 4 | B5: 11.2 | C5: 0.28 | D5: 0.56 | E5: 1.9 | F5: 0.075 | G5: 17 | H5: 60 | I5: 0.998 | J5: 3.16 | K5: 0.58 | L5: 9.8 | M5: 6
A6: 5 | B6: 7.4 | C6: 0.66 | D6: 0 | E6: 1.8 | F6: 0.075 | G6: 13 | H6: 40 | I6: 0.9978 | J6: 3.51 | K6: 0.56 | L6: 9.4 | M6: 5
A7: 6 | B7: 7.9 | C7: 0.6 | D7: 0.06 | E7: 1.6 | F7: 0.069 | G7: 15 | H7: 59 | I7: 0.9964 | J7: 3.3 | K7: 0.46 | L7: 9.4 | M7: 5
A8: 7 | B8: 7.3 | C8: 0.65 | D8: 0 | E8: 1.2 | F8: 0.065 | G8: 15 | H8: 21 | I8: 0.9946 | J8: 3.39 | K8: 0.47 | L8: 10 | M8: 7
A9: 8 | B9: 7.8 | C9: 0.58 | D9: 0.02 | E9: 2 | F9: 0.073 | G9: 9 | H9: 18 | I9: 0.9968 | J9: 3.36 | K9: 0.57 | L9: 9.5 | M9: 7
A10: 9 | B10: 7.5 | C10: 0.5 | D10: 0.36 | E10: 6.1 | F10: 0.071 | G10: 17 | H10: 102 | I10: 0.9978 | J10: 3.35 | K10: 0.8 | L10: 10.5 | M10: 5
A11: 10 | B11: 6.7 | C11: 0.58 | D11: 0.08 | E11: 1.8 | F11: 0.097 | G11: 15 | H11: 65 | I11: 0.9959 | J11: 3.28 | K11: 0.54 | L11: 9.2 | M11: 5
A12: 11 | B12: 5.6 | C12: 0.615 | D12: 0 | E12: 1.6 | F12: 0.089 | G12: 16 | H12: 59 | I12: 0.9943 | J12: 3.58 | K12: 0.52 | L12: 9.9 | M12: 5
A13: 12 | B13: 7.8 | C13: 0.61 | D13: 0.29 | E13: 1.6 | F13: 0.114 | G13: 9 | H13: 29 | I13: 0.9974 | J13: 3.26 | K13: 1.56 | L13: 9.1 | M13: 5
... A1360: 1359 | B1360: 6 | C1360: 0.31 | D1360: 0.47 | E1360: 3.6 | F1360: 0.067 | G1360: 18 | H1360: 42 | I1360: 0.99549 | J1360: 3.39 | K1360: 0.66 | L1360: 11 | M1360: 6

Sheet 2_Cleaning_Log
A1: Data Cleaning Log
A2: All values below are live formulas that audit 1_Raw_Data and 2_Clean_Data.
A4: Check | B4: Value | C4: What it means
A5: Rows in raw data | B5: =COUNTA('1_Raw_Data'!A2:A1600) -> 1599 | C5: Imported from winequality-red.csv (semicolon-delimited)
A6: Rows in clean data | B6: =COUNTA('2_Clean_Data'!A2:A1360) -> 1359 | C6: After removing exact duplicate rows (first occurrence kept)
A7: Duplicate rows removed | B7: =B5-B6 -> 240 | C7: Raw rows minus clean rows
A8: % of raw rows removed | B8: =B7/B5 -> 0.15009381 | C8: Share of raw dataset that was duplicated
A9: Missing cells - raw | B9: =COUNTBLANK('1_Raw_Data'!A2:L1600) -> 0 | C9: No blanks found, so no imputation was needed
A10: Missing cells - clean | B10: =COUNTBLANK('2_Clean_Data'!B2:M1360) -> 0 | C10: Must be 0 after cleaning
A11: Non-numeric cells - clean | B11: =ROWS('2_Clean_Data'!B2:M1360)*COLUMNS('2_Clean_Data'!B2:M1360)-COUNT('2_Clean_Data'!B2:M1360) -> 0 | C11: Must be 0: every measurement is stored as a number
A14: Column-level data type & range check (clean data)
A15: Column | B15: Count | C15: Missing | D15: Min | E15: Max | F15: Mean | G15: Type check | H15: Format applied
A16: Fixed_Acidity | B16: =COUNT('2_Clean_Data'!B2:B1360) -> 1359 | C16: =COUNTBLANK('2_Clean_Data'!B2:B1360) -> 0 | D16: =MIN('2_Clean_Data'!B2:B1360) -> 4.6 | E16: =MAX('2_Clean_Data'!B2:B1360) -> 15.9 | F16: =AVERAGE('2_Clean_Data'!B2:B1360) -> 8.310596 | G16: =IF(AND(B16=$B$6,C16=0),"Numeric OK","CHECK") -> Numeric OK | H16: Number, 1 decimal
A17: Volatile_Acidity | B17: =COUNT('2_Clean_Data'!C2:C1360) -> 1359 | C17: =COUNTBLANK('2_Clean_Data'!C2:C1360) -> 0 | D17: =MIN('2_Clean_Data'!C2:C1360) -> 0.12 | E17: =MAX('2_Clean_Data'!C2:C1360) -> 1.58 | F17: =AVERAGE('2_Clean_Data'!C2:C1360) -> 0.52947756 | G17: =IF(AND(B17=$B$6,C17=0),"Numeric OK","CHECK") -> Numeric OK | H17: Number, 3 decimals
A18: Citric_Acid | B18: =COUNT('2_Clean_Data'!D2:D1360) -> 1359 | C18: =COUNTBLANK('2_Clean_Data'!D2:D1360) -> 0 | D18: =MIN('2_Clean_Data'!D2:D1360) -> 0 | E18: =MAX('2_Clean_Data'!D2:D1360) -> 1 | F18: =AVERAGE('2_Clean_Data'!D2:D1360) -> 0.2723326 | G18: =IF(AND(B18=$B$6,C18=0),"Numeric OK","CHECK") -> Numeric OK | H18: Number, 2 decimals
A19: Residual_Sugar | B19: =COUNT('2_Clean_Data'!E2:E1360) -> 1359 | C19: =COUNTBLANK('2_Clean_Data'!E2:E1360) -> 0 | D19: =MIN('2_Clean_Data'!E2:E1360) -> 0.9 | E19: =MAX('2_Clean_Data'!E2:E1360) -> 15.5 | F19: =AVERAGE('2_Clean_Data'!E2:E1360) -> 2.5233996 | G19: =IF(AND(B19=$B$6,C19=0),"Numeric OK","CHECK") -> Numeric OK | H19: Number, 1 decimal
A20: Chlorides | B20: =COUNT('2_Clean_Data'!F2:F1360) -> 1359 | C20: =COUNTBLANK('2_Clean_Data'!F2:F1360) -> 0 | D20: =MIN('2_Clean_Data'!F2:F1360) -> 0.012 | E20: =MAX('2_Clean_Data'!F2:F1360) -> 0.611 | F20: =AVERAGE('2_Clean_Data'!F2:F1360) -> 0.08812362 | G20: =IF(AND(B20=$B$6,C20=0),"Numeric OK","CHECK") -> Numeric OK | H20: Number, 3 decimals
A21: Free_Sulfur_Dioxide | B21: =COUNT('2_Clean_Data'!G2:G1360) -> 1359 | C21: =COUNTBLANK('2_Clean_Data'!G2:G1360) -> 0 | D21: =MIN('2_Clean_Data'!G2:G1360) -> 1 | E21: =MAX('2_Clean_Data'!G2:G1360) -> 72 | F21: =AVERAGE('2_Clean_Data'!G2:G1360) -> 15.893304 | G21: =IF(AND(B21=$B$6,C21=0),"Numeric OK","CHECK") -> Numeric OK | H21: Number, 1 decimal
A22: Total_Sulfur_Dioxide | B22: =COUNT('2_Clean_Data'!H2:H1360) -> 1359 | C22: =COUNTBLANK('2_Clean_Data'!H2:H1360) -> 0 | D22: =MIN('2_Clean_Data'!H2:H1360) -> 6 | E22: =MAX('2_Clean_Data'!H2:H1360) -> 289 | F22: =AVERAGE('2_Clean_Data'!H2:H1360) -> 46.825975 | G22: =IF(AND(B22=$B$6,C22=0),"Numeric OK","CHECK") -> Numeric OK | H22: Number, 1 decimal
A23: Density | B23: =COUNT('2_Clean_Data'!I2:I1360) -> 1359 | C23: =COUNTBLANK('2_Clean_Data'!I2:I1360) -> 0 | D23: =MIN('2_Clean_Data'!I2:I1360) -> 0.99007 | E23: =MAX('2_Clean_Data'!I2:I1360) -> 1.00369 | F23: =AVERAGE('2_Clean_Data'!I2:I1360) -> 0.99670895 | G23: =IF(AND(B23=$B$6,C23=0),"Numeric OK","CHECK") -> Numeric OK | H23: Number, 5 decimals
A24: pH | B24: =COUNT('2_Clean_Data'!J2:J1360) -> 1359 | C24: =COUNTBLANK('2_Clean_Data'!J2:J1360) -> 0 | D24: =MIN('2_Clean_Data'!J2:J1360) -> 2.74 | E24: =MAX('2_Clean_Data'!J2:J1360) -> 4.01 | F24: =AVERAGE('2_Clean_Data'!J2:J1360) -> 3.3097866 | G24: =IF(AND(B24=$B$6,C24=0),"Numeric OK","CHECK") -> Numeric OK | H24: Number, 2 decimals
A25: Sulphates | B25: =COUNT('2_Clean_Data'!K2:K1360) -> 1359 | C25: =COUNTBLANK('2_Clean_Data'!K2:K1360) -> 0 | D25: =MIN('2_Clean_Data'!K2:K1360) -> 0.33 | E25: =MAX('2_Clean_Data'!K2:K1360) -> 2 | F25: =AVERAGE('2_Clean_Data'!K2:K1360) -> 0.65870493 | G25: =IF(AND(B25=$B$6,C25=0),"Numeric OK","CHECK") -> Numeric OK | H25: Number, 2 decimals
A26: Alcohol | B26: =COUNT('2_Clean_Data'!L2:L1360) -> 1359 | C26: =COUNTBLANK('2_Clean_Data'!L2:L1360) -> 0 | D26: =MIN('2_Clean_Data'!L2:L1360) -> 8.4 | E26: =MAX('2_Clean_Data'!L2:L1360) -> 14.9 | F26: =AVERAGE('2_Clean_Data'!L2:L1360) -> 10.432315 | G26: =IF(AND(B26=$B$6,C26=0),"Numeric OK","CHECK") -> Numeric OK | H26: Number, 1 decimal
A27: Quality | B27: =COUNT('2_Clean_Data'!M2:M1360) -> 1359 | C27: =COUNTBLANK('2_Clean_Data'!M2:M1360) -> 0 | D27: =MIN('2_Clean_Data'!M2:M1360) -> 3 | E27: =MAX('2_Clean_Data'!M2:M1360) -> 8 | F27: =AVERAGE('2_Clean_Data'!M2:M1360) -> 5.6232524 | G27: =IF(AND(B27=$B$6,C27=0),"Numeric OK","CHECK") -> Numeric OK | H27: Whole number

Sheet 3_Pivot_Tables
A1: Native Excel PivotTables
A4: PivotTable 1 - Quality summary (source: 2_Clean_Data)
A6: Filter
B8: Data
A9: Quality | B9: Count - Wine_ID | C9: Average - Alcohol | D9: Average - Volatile_Acidity | E9: Average - pH | F9: Average - Sulphates
A10: 3 | B10: 10 | C10: 9.955 | D10: 0.8845 | E10: 3.398 | F10: 0.57
A11: 4 | B11: 53 | C11: 10.265094 | D11: 0.69396226 | E11: 3.3815094 | F11: 0.59641509
A12: 5 | B12: 577 | C12: 9.8885615 | D12: 0.57859619 | E12: 3.3008146 | F12: 0.62357019
A13: 6 | B13: 535 | C13: 10.658879 | D13: 0.49608411 | E13: 3.318 | F13: 0.67454206
A14: 7 | B14: 167 | C14: 11.491118 | D14: 0.40365269 | E14: 3.2900599 | F14: 0.74263473
A15: 8 | B15: 17 | C15: 12.158824 | D15: 0.42764706 | E15: 3.2741176 | F15: 0.77470588
A16: Total Result | B16: 1359 | C16: 10.432315 | D16: 0.52947756 | E16: 3.3097866 | F16: 0.65870493
A19: PivotTable 2 - Alcohol band x Quality, wine count (source: 4_Formulas)
A21: Filter
A23: Count - Wine_ID | B23: Quality
A24: Alcohol_Band | B24: 3 | C24: 4 | D24: 5 | E24: 6 | F24: 7 | G24: 8 | H24: Total Result
A25: High | C25: 5 | D25: 20 | E25: 121 | F25: 89 | G25: 12 | H25: 247
A26: Low | B26: 6 | C26: 24 | D26: 380 | E26: 156 | F26: 9 | G26: 1 | H26: 576
A27: Medium | B27: 4 | C27: 24 | D27: 177 | E27: 258 | F27: 69 | G27: 4 | H27: 536
A28: Total Result | B28: 10 | C28: 53 | D28: 577 | E28: 535 | F28: 167 | G28: 17 | H28: 1359
A31: PivotTable 3 - Wine profile summary (source: 4_Formulas)
A33: Filter
B35: Data
A36: Wine_Profile | B36: Count - Wine_ID | C36: Average - Alcohol | D36: Average - Quality
A37: Poor | B37: 63 | C37: 10.215873 | D37: 3.8412698
A38: Premium | B38: 101 | C38: 12.30066 | D38: 7.1188119
A39: Solid | B39: 560 | C39: 10.658661 | D39: 6.1553571
A40: Standard | B40: 635 | C40: 9.9570079 | D40: 5.0929134
A41: Total Result | B41: 1359 | C41: 10.432315 | D41: 5.6232524
A43: PivotTable 4 - Quality grade x Acidity flag, wine count (source: 4_Formulas)
A45: Filter
A47: Count - Wine_ID | B47: Acidity_Flag
A48: Quality_Grade | B48: Above limit | C48: OK | D48: Total Result
A49: Above Average | B49: 57 | C49: 478 | D49: 535
A50: Average | B50: 110 | C50: 467 | D50: 577
A51: Excellent | B51: 1 | C51: 16 | D51: 17
A52: Good | B52: 5 | C52: 162 | D52: 167
A53: Poor | B53: 29 | C53: 34 | D53: 63
A54: Total Result | B54: 202 | C54: 1157 | D54: 1359

Sheet 3_Summary_Tables
A1: Summary Tables (formula-driven)
A2: Live COUNTIFS / AVERAGEIFS tables on dynamic named ranges. They feed the charts and dashboard. Native PivotTables are on 3_Pivot_Tables.
A3: Summary 1 - Quality summary
A4: Quality | B4: Wine_Count | C4: % of Total | D4: Avg_Alcohol | E4: Avg_Volatile_Acidity | F4: Avg_Citric_Acid | G4: Avg_pH | H4: Avg_Sulphates
A5: 3 | B5: =COUNTIFS(rngQuality,$A5) -> 10 | C5: =B5/$B$11 -> 0.0073583517 | D5: =AVERAGEIFS(rngAlcohol,rngQuality,$A5) -> 9.955 | E5: =AVERAGEIFS(rngVolatile,rngQuality,$A5) -> 0.8845 | F5: =AVERAGEIFS(rngCitric,rngQuality,$A5) -> 0.171 | G5: =AVERAGEIFS(rngPH,rngQuality,$A5) -> 3.398 | H5: =AVERAGEIFS(rngSulphates,rngQuality,$A5) -> 0.57
A6: 4 | B6: =COUNTIFS(rngQuality,$A6) -> 53 | C6: =B6/$B$11 -> 0.038999264 | D6: =AVERAGEIFS(rngAlcohol,rngQuality,$A6) -> 10.265094 | E6: =AVERAGEIFS(rngVolatile,rngQuality,$A6) -> 0.69396226 | F6: =AVERAGEIFS(rngCitric,rngQuality,$A6) -> 0.17415094 | G6: =AVERAGEIFS(rngPH,rngQuality,$A6) -> 3.3815094 | H6: =AVERAGEIFS(rngSulphates,rngQuality,$A6) -> 0.59641509
A7: 5 | B7: =COUNTIFS(rngQuality,$A7) -> 577 | C7: =B7/$B$11 -> 0.42457689 | D7: =AVERAGEIFS(rngAlcohol,rngQuality,$A7) -> 9.8885615 | E7: =AVERAGEIFS(rngVolatile,rngQuality,$A7) -> 0.57859619 | F7: =AVERAGEIFS(rngCitric,rngQuality,$A7) -> 0.2445234 | G7: =AVERAGEIFS(rngPH,rngQuality,$A7) -> 3.3008146 | H7: =AVERAGEIFS(rngSulphates,rngQuality,$A7) -> 0.62357019
A8: 6 | B8: =COUNTIFS(rngQuality,$A8) -> 535 | C8: =B8/$B$11 -> 0.39367182 | D8: =AVERAGEIFS(rngAlcohol,rngQuality,$A8) -> 10.658879 | E8: =AVERAGEIFS(rngVolatile,rngQuality,$A8) -> 0.49608411 | F8: =AVERAGEIFS(rngCitric,rngQuality,$A8) -> 0.27936449 | G8: =AVERAGEIFS(rngPH,rngQuality,$A8) -> 3.318 | H8: =AVERAGEIFS(rngSulphates,rngQuality,$A8) -> 0.67454206
A9: 7 | B9: =COUNTIFS(rngQuality,$A9) -> 167 | C9: =B9/$B$11 -> 0.12288447 | D9: =AVERAGEIFS(rngAlcohol,rngQuality,$A9) -> 11.491118 | E9: =AVERAGEIFS(rngVolatile,rngQuality,$A9) -> 0.40365269 | F9: =AVERAGEIFS(rngCitric,rngQuality,$A9) -> 0.37185629 | G9: =AVERAGEIFS(rngPH,rngQuality,$A9) -> 3.2900599 | H9: =AVERAGEIFS(rngSulphates,rngQuality,$A9) -> 0.74263473
A10: 8 | B10: =COUNTIFS(rngQuality,$A10) -> 17 | C10: =B10/$B$11 -> 0.012509198 | D10: =AVERAGEIFS(rngAlcohol,rngQuality,$A10) -> 12.158824 | E10: =AVERAGEIFS(rngVolatile,rngQuality,$A10) -> 0.42764706 | F10: =AVERAGEIFS(rngCitric,rngQuality,$A10) -> 0.38294118 | G10: =AVERAGEIFS(rngPH,rngQuality,$A10) -> 3.2741176 | H10: =AVERAGEIFS(rngSulphates,rngQuality,$A10) -> 0.77470588
A11: Grand Total | B11: =SUM(B5:B10) -> 1359 | C11: =SUM(C5:C10) -> 1 | D11: =AVERAGE(rngAlcohol) -> 10.432315 | E11: =AVERAGE(rngVolatile) -> 0.52947756 | F11: =AVERAGE(rngCitric) -> 0.2723326 | G11: =AVERAGE(rngPH) -> 3.3097866 | H11: =AVERAGE(rngSulphates) -> 0.65870493
A14: Summary 2 - Alcohol band x Quality (wine count)
A15: Alcohol_Band | B15: Lower (>=) | C15: Upper (<) | D15: 3 | E15: 4 | F15: 5 | G15: 6 | H15: 7 | I15: 8 | J15: Total
A16: Low | B16: 0 | C16: 10 | D16: =COUNTIFS(rngQuality,D$15,rngAlcohol,">="&$B16,rngAlcohol,"<"&$C16) -> 6 | E16: =COUNTIFS(rngQuality,E$15,rngAlcohol,">="&$B16,rngAlcohol,"<"&$C16) -> 24 | F16: =COUNTIFS(rngQuality,F$15,rngAlcohol,">="&$B16,rngAlcohol,"<"&$C16) -> 380 | G16: =COUNTIFS(rngQuality,G$15,rngAlcohol,">="&$B16,rngAlcohol,"<"&$C16) -> 156 | H16: =COUNTIFS(rngQuality,H$15,rngAlcohol,">="&$B16,rngAlcohol,"<"&$C16) -> 9 | I16: =COUNTIFS(rngQuality,I$15,rngAlcohol,">="&$B16,rngAlcohol,"<"&$C16) -> 1 | J16: =SUM(D16:I16) -> 576 | L16: Blue cells are the band cut-offs (% alcohol by volume). Change them and every sheet that uses bands updates.
A17: Medium | B17: =C16 -> 10 | C17: 11.5 | D17: =COUNTIFS(rngQuality,D$15,rngAlcohol,">="&$B17,rngAlcohol,"<"&$C17) -> 4 | E17: =COUNTIFS(rngQuality,E$15,rngAlcohol,">="&$B17,rngAlcohol,"<"&$C17) -> 24 | F17: =COUNTIFS(rngQuality,F$15,rngAlcohol,">="&$B17,rngAlcohol,"<"&$C17) -> 177 | G17: =COUNTIFS(rngQuality,G$15,rngAlcohol,">="&$B17,rngAlcohol,"<"&$C17) -> 258 | H17: =COUNTIFS(rngQuality,H$15,rngAlcohol,">="&$B17,rngAlcohol,"<"&$C17) -> 69 | I17: =COUNTIFS(rngQuality,I$15,rngAlcohol,">="&$B17,rngAlcohol,"<"&$C17) -> 4 | J17: =SUM(D17:I17) -> 536
A18: High | B18: =C17 -> 11.5 | C18: 100 | D18: =COUNTIFS(rngQuality,D$15,rngAlcohol,">="&$B18,rngAlcohol,"<"&$C18) -> 0 | E18: =COUNTIFS(rngQuality,E$15,rngAlcohol,">="&$B18,rngAlcohol,"<"&$C18) -> 5 | F18: =COUNTIFS(rngQuality,F$15,rngAlcohol,">="&$B18,rngAlcohol,"<"&$C18) -> 20 | G18: =COUNTIFS(rngQuality,G$15,rngAlcohol,">="&$B18,rngAlcohol,"<"&$C18) -> 121 | H18: =COUNTIFS(rngQuality,H$15,rngAlcohol,">="&$B18,rngAlcohol,"<"&$C18) -> 89 | I18: =COUNTIFS(rngQuality,I$15,rngAlcohol,">="&$B18,rngAlcohol,"<"&$C18) -> 12 | J18: =SUM(D18:I18) -> 247
A19: Total | D19: =SUM(D16:D18) -> 10 | E19: =SUM(E16:E18) -> 53 | F19: =SUM(F16:F18) -> 577 | G19: =SUM(G16:G18) -> 535 | H19: =SUM(H16:H18) -> 167 | I19: =SUM(I16:I18) -> 17 | J19: =SUM(J16:J18) -> 1359
A22: Summary 3 - Average of each property by quality
A23: Property | B23: 3 | C23: 4 | D23: 5 | E23: 6 | F23: 7 | G23: 8 | H23: All wines
A24: ='2_Clean_Data'!B1 -> Fixed_Acidity | B24: =AVERAGEIFS(INDEX(rngData,0,MATCH($A24,'2_Clean_Data'!$B$1:$M$1,0)),rngQuality,B$23) -> 8.36 | C24: =AVERAGEIFS(INDEX(rngData,0,MATCH($A24,'2_Clean_Data'!$B$1:$M$1,0)),rngQuality,C$23) -> 7.7792453 | D24: =AVERAGEIFS(INDEX(rngData,0,MATCH($A24,'2_Clean_Data'!$B$1:$M$1,0)),rngQuality,D$23) -> 8.1712305 | E24: =AVERAGEIFS(INDEX(rngData,0,MATCH($A24,'2_Clean_Data'!$B$1:$M$1,0)),rngQuality,E$23) -> 8.3373832 | F24: =AVERAGEIFS(INDEX(rngData,0,MATCH($A24,'2_Clean_Data'!$B$1:$M$1,0)),rngQuality,F$23) -> 8.8586826 | G24: =AVERAGEIFS(INDEX(rngData,0,MATCH($A24,'2_Clean_Data'!$B$1:$M$1,0)),rngQuality,G$23) -> 8.4411765 | H24: =AVERAGE(INDEX(rngData,0,MATCH($A24,'2_Clean_Data'!$B$1:$M$1,0))) -> 8.310596
A25: ='2_Clean_Data'!C1 -> Volatile_Acidity | B25: =AVERAGEIFS(INDEX(rngData,0,MATCH($A25,'2_Clean_Data'!$B$1:$M$1,0)),rngQuality,B$23) -> 0.8845 | C25: =AVERAGEIFS(INDEX(rngData,0,MATCH($A25,'2_Clean_Data'!$B$1:$M$1,0)),rngQuality,C$23) -> 0.69396226 | D25: =AVERAGEIFS(INDEX(rngData,0,MATCH($A25,'2_Clean_Data'!$B$1:$M$1,0)),rngQuality,D$23) -> 0.57859619 | E25: =AVERAGEIFS(INDEX(rngData,0,MATCH($A25,'2_Clean_Data'!$B$1:$M$1,0)),rngQuality,E$23) -> 0.49608411 | F25: =AVERAGEIFS(INDEX(rngData,0,MATCH($A25,'2_Clean_Data'!$B$1:$M$1,0)),rngQuality,F$23) -> 0.40365269 | G25: =AVERAGEIFS(INDEX(rngData,0,MATCH($A25,'2_Clean_Data'!$B$1:$M$1,0)),rngQuality,G$23) -> 0.42764706 | H25: =AVERAGE(INDEX(rngData,0,MATCH($A25,'2_Clean_Data'!$B$1:$M$1,0))) -> 0.52947756
A26: ='2_Clean_Data'!D1 -> Citric_Acid | B26: =AVERAGEIFS(INDEX(rngData,0,MATCH($A26,'2_Clean_Data'!$B$1:$M$1,0)),rngQuality,B$23) -> 0.171 | C26: =AVERAGEIFS(INDEX(rngData,0,MATCH($A26,'2_Clean_Data'!$B$1:$M$1,0)),rngQuality,C$23) -> 0.17415094 | D26: =AVERAGEIFS(INDEX(rngData,0,MATCH($A26,'2_Clean_Data'!$B$1:$M$1,0)),rngQuality,D$23) -> 0.2445234 | E26: =AVERAGEIFS(INDEX(rngData,0,MATCH($A26,'2_Clean_Data'!$B$1:$M$1,0)),rngQuality,E$23) -> 0.27936449 | F26: =AVERAGEIFS(INDEX(rngData,0,MATCH($A26,'2_Clean_Data'!$B$1:$M$1,0)),rngQuality,F$23) -> 0.37185629 | G26: =AVERAGEIFS(INDEX(rngData,0,MATCH($A26,'2_Clean_Data'!$B$1:$M$1,0)),rngQuality,G$23) -> 0.38294118 | H26: =AVERAGE(INDEX(rngData,0,MATCH($A26,'2_Clean_Data'!$B$1:$M$1,0))) -> 0.2723326
A27: ='2_Clean_Data'!E1 -> Residual_Sugar | B27: =AVERAGEIFS(INDEX(rngData,0,MATCH($A27,'2_Clean_Data'!$B$1:$M$1,0)),rngQuality,B$23) -> 2.635 | C27: =AVERAGEIFS(INDEX(rngData,0,MATCH($A27,'2_Clean_Data'!$B$1:$M$1,0)),rngQuality,C$23) -> 2.6943396 | D27: =AVERAGEIFS(INDEX(rngData,0,MATCH($A27,'2_Clean_Data'!$B$1:$M$1,0)),rngQuality,D$23) -> 2.5095321 | E27: =AVERAGEIFS(INDEX(rngData,0,MATCH($A27,'2_Clean_Data'!$B$1:$M$1,0)),rngQuality,E$23) -> 2.4572897 | F27: =AVERAGEIFS(INDEX(rngData,0,MATCH($A27,'2_Clean_Data'!$B$1:$M$1,0)),rngQuality,F$23) -> 2.7167665 | G27: =AVERAGEIFS(INDEX(rngData,0,MATCH($A27,'2_Clean_Data'!$B$1:$M$1,0)),rngQuality,G$23) -> 2.5764706 | H27: =AVERAGE(INDEX(rngData,0,MATCH($A27,'2_Clean_Data'!$B$1:$M$1,0))) -> 2.5233996
A28: ='2_Clean_Data'!F1 -> Chlorides | B28: =AVERAGEIFS(INDEX(rngData,0,MATCH($A28,'2_Clean_Data'!$B$1:$M$1,0)),rngQuality,B$23) -> 0.1225 | C28: =AVERAGEIFS(INDEX(rngData,0,MATCH($A28,'2_Clean_Data'!$B$1:$M$1,0)),rngQuality,C$23) -> 0.090679245 | D28: =AVERAGEIFS(INDEX(rngData,0,MATCH($A28,'2_Clean_Data'!$B$1:$M$1,0)),rngQuality,D$23) -> 0.093970537 | E28: =AVERAGEIFS(INDEX(rngData,0,MATCH($A28,'2_Clean_Data'!$B$1:$M$1,0)),rngQuality,E$23) -> 0.085074766 | F28: =AVERAGEIFS(INDEX(rngData,0,MATCH($A28,'2_Clean_Data'!$B$1:$M$1,0)),rngQuality,F$23) -> 0.076832335 | G28: =AVERAGEIFS(INDEX(rngData,0,MATCH($A28,'2_Clean_Data'!$B$1:$M$1,0)),rngQuality,G$23) -> 0.068352941 | H28: =AVERAGE(INDEX(rngData,0,MATCH($A28,'2_Clean_Data'!$B$1:$M$1,0))) -> 0.08812362
A29: ='2_Clean_Data'!G1 -> Free_Sulfur_Dioxide | B29: =AVERAGEIFS(INDEX(rngData,0,MATCH($A29,'2_Clean_Data'!$B$1:$M$1,0)),rngQuality,B$23) -> 11 | C29: =AVERAGEIFS(INDEX(rngData,0,MATCH($A29,'2_Clean_Data'!$B$1:$M$1,0)),rngQuality,C$23) -> 12.264151 | D29: =AVERAGEIFS(INDEX(rngData,0,MATCH($A29,'2_Clean_Data'!$B$1:$M$1,0)),rngQuality,D$23) -> 17.161179 | E29: =AVERAGEIFS(INDEX(rngData,0,MATCH($A29,'2_Clean_Data'!$B$1:$M$1,0)),rngQuality,E$23) -> 15.637383 | F29: =AVERAGEIFS(INDEX(rngData,0,MATCH($A29,'2_Clean_Data'!$B$1:$M$1,0)),rngQuality,F$23) -> 13.994012 | G29: =AVERAGEIFS(INDEX(rngData,0,MATCH($A29,'2_Clean_Data'!$B$1:$M$1,0)),rngQuality,G$23) -> 13.764706 | H29: =AVERAGE(INDEX(rngData,0,MATCH($A29,'2_Clean_Data'!$B$1:$M$1,0))) -> 15.893304
A30: ='2_Clean_Data'!H1 -> Total_Sulfur_Dioxide | B30: =AVERAGEIFS(INDEX(rngData,0,MATCH($A30,'2_Clean_Data'!$B$1:$M$1,0)),rngQuality,B$23) -> 24.9 | C30: =AVERAGEIFS(INDEX(rngData,0,MATCH($A30,'2_Clean_Data'!$B$1:$M$1,0)),rngQuality,C$23) -> 36.245283 | D30: =AVERAGEIFS(INDEX(rngData,0,MATCH($A30,'2_Clean_Data'!$B$1:$M$1,0)),rngQuality,D$23) -> 57.406412 | E30: =AVERAGEIFS(INDEX(rngData,0,MATCH($A30,'2_Clean_Data'!$B$1:$M$1,0)),rngQuality,E$23) -> 40.816822 | F30: =AVERAGEIFS(INDEX(rngData,0,MATCH($A30,'2_Clean_Data'!$B$1:$M$1,0)),rngQuality,F$23) -> 35.449102 | G30: =AVERAGEIFS(INDEX(rngData,0,MATCH($A30,'2_Clean_Data'!$B$1:$M$1,0)),rngQuality,G$23) -> 34.470588 | H30: =AVERAGE(INDEX(rngData,0,MATCH($A30,'2_Clean_Data'!$B$1:$M$1,0))) -> 46.825975
A31: ='2_Clean_Data'!I1 -> Density | B31: =AVERAGEIFS(INDEX(rngData,0,MATCH($A31,'2_Clean_Data'!$B$1:$M$1,0)),rngQuality,B$23) -> 0.997464 | C31: =AVERAGEIFS(INDEX(rngData,0,MATCH($A31,'2_Clean_Data'!$B$1:$M$1,0)),rngQuality,C$23) -> 0.99654245 | D31: =AVERAGEIFS(INDEX(rngData,0,MATCH($A31,'2_Clean_Data'!$B$1:$M$1,0)),rngQuality,D$23) -> 0.99708225 | E31: =AVERAGEIFS(INDEX(rngData,0,MATCH($A31,'2_Clean_Data'!$B$1:$M$1,0)),rngQuality,E$23) -> 0.99656535 | F31: =AVERAGEIFS(INDEX(rngData,0,MATCH($A31,'2_Clean_Data'!$B$1:$M$1,0)),rngQuality,F$23) -> 0.99605108 | G31: =AVERAGEIFS(INDEX(rngData,0,MATCH($A31,'2_Clean_Data'!$B$1:$M$1,0)),rngQuality,G$23) -> 0.99509529 | H31: =AVERAGE(INDEX(rngData,0,MATCH($A31,'2_Clean_Data'!$B$1:$M$1,0))) -> 0.99670895
A32: ='2_Clean_Data'!J1 -> pH | B32: =AVERAGEIFS(INDEX(rngData,0,MATCH($A32,'2_Clean_Data'!$B$1:$M$1,0)),rngQuality,B$23) -> 3.398 | C32: =AVERAGEIFS(INDEX(rngData,0,MATCH($A32,'2_Clean_Data'!$B$1:$M$1,0)),rngQuality,C$23) -> 3.3815094 | D32: =AVERAGEIFS(INDEX(rngData,0,MATCH($A32,'2_Clean_Data'!$B$1:$M$1,0)),rngQuality,D$23) -> 3.3008146 | E32: =AVERAGEIFS(INDEX(rngData,0,MATCH($A32,'2_Clean_Data'!$B$1:$M$1,0)),rngQuality,E$23) -> 3.318 | F32: =AVERAGEIFS(INDEX(rngData,0,MATCH($A32,'2_Clean_Data'!$B$1:$M$1,0)),rngQuality,F$23) -> 3.2900599 | G32: =AVERAGEIFS(INDEX(rngData,0,MATCH($A32,'2_Clean_Data'!$B$1:$M$1,0)),rngQuality,G$23) -> 3.2741176 | H32: =AVERAGE(INDEX(rngData,0,MATCH($A32,'2_Clean_Data'!$B$1:$M$1,0))) -> 3.3097866
A33: ='2_Clean_Data'!K1 -> Sulphates | B33: =AVERAGEIFS(INDEX(rngData,0,MATCH($A33,'2_Clean_Data'!$B$1:$M$1,0)),rngQuality,B$23) -> 0.57 | C33: =AVERAGEIFS(INDEX(rngData,0,MATCH($A33,'2_Clean_Data'!$B$1:$M$1,0)),rngQuality,C$23) -> 0.59641509 | D33: =AVERAGEIFS(INDEX(rngData,0,MATCH($A33,'2_Clean_Data'!$B$1:$M$1,0)),rngQuality,D$23) -> 0.62357019 | E33: =AVERAGEIFS(INDEX(rngData,0,MATCH($A33,'2_Clean_Data'!$B$1:$M$1,0)),rngQuality,E$23) -> 0.67454206 | F33: =AVERAGEIFS(INDEX(rngData,0,MATCH($A33,'2_Clean_Data'!$B$1:$M$1,0)),rngQuality,F$23) -> 0.74263473 | G33: =AVERAGEIFS(INDEX(rngData,0,MATCH($A33,'2_Clean_Data'!$B$1:$M$1,0)),rngQuality,G$23) -> 0.77470588 | H33: =AVERAGE(INDEX(rngData,0,MATCH($A33,'2_Clean_Data'!$B$1:$M$1,0))) -> 0.65870493
A34: ='2_Clean_Data'!L1 -> Alcohol | B34: =AVERAGEIFS(INDEX(rngData,0,MATCH($A34,'2_Clean_Data'!$B$1:$M$1,0)),rngQuality,B$23) -> 9.955 | C34: =AVERAGEIFS(INDEX(rngData,0,MATCH($A34,'2_Clean_Data'!$B$1:$M$1,0)),rngQuality,C$23) -> 10.265094 | D34: =AVERAGEIFS(INDEX(rngData,0,MATCH($A34,'2_Clean_Data'!$B$1:$M$1,0)),rngQuality,D$23) -> 9.8885615 | E34: =AVERAGEIFS(INDEX(rngData,0,MATCH($A34,'2_Clean_Data'!$B$1:$M$1,0)),rngQuality,E$23) -> 10.658879 | F34: =AVERAGEIFS(INDEX(rngData,0,MATCH($A34,'2_Clean_Data'!$B$1:$M$1,0)),rngQuality,F$23) -> 11.491118 | G34: =AVERAGEIFS(INDEX(rngData,0,MATCH($A34,'2_Clean_Data'!$B$1:$M$1,0)),rngQuality,G$23) -> 12.158824 | H34: =AVERAGE(INDEX(rngData,0,MATCH($A34,'2_Clean_Data'!$B$1:$M$1,0))) -> 10.432315

Sheet 4_Formulas
A1: Advanced Formulas
A2: VLOOKUP, INDEX-MATCH, IF and nested IF/AND applied to every clean wine record.
A3: Method: link | B3: Method: INDEX-MATCH | C3: Method: VLOOKUP | D3: Method: INDEX-MATCH | E3: Method: nested IF | F3: Method: INDEX-MATCH | G3: Method: INDEX-MATCH | H3: Method: nested IF | I3: Method: IF | J3: Method: nested IF + AND
A4: Wine_ID | B4: Quality | C4: Quality_Grade | D4: Alcohol | E4: Alcohol_Band | F4: Volatile_Acidity | G4: Total_SO2 | H4: Sulfur_Risk | I4: Acidity_Flag | J4: Wine_Profile | L4: Parameters (editable)
A5: ='2_Clean_Data'!A2 -> 1 | B5: =INDEX('2_Clean_Data'!$M$2:$M$1360,MATCH($A5,'2_Clean_Data'!$A$2:$A$1360,0)) -> 5 | C5: =VLOOKUP(B5,$L$12:$N$17,2,FALSE()) -> Average | D5: =INDEX('2_Clean_Data'!$L$2:$L$1360,MATCH($A5,'2_Clean_Data'!$A$2:$A$1360,0)) -> 9.4 | E5: =IF(D5<'3_Summary_Tables'!$C$16,"Low",IF(D5<'3_Summary_Tables'!$C$17,"Medium","High")) -> Low | F5: =INDEX('2_Clean_Data'!$C$2:$C$1360,MATCH($A5,'2_Clean_Data'!$A$2:$A$1360,0)) -> 0.7 | G5: =INDEX('2_Clean_Data'!$H$2:$H$1360,MATCH($A5,'2_Clean_Data'!$A$2:$A$1360,0)) -> 34 | H5: =IF(G5>$M$8,"High",IF(G5>$M$7,"Moderate","Low")) -> Low | I5: =IF(F5>$M$6,"Above limit","OK") -> OK | J5: =IF(AND(B5>=7,E5="High"),"Premium",IF(AND(B5>=6,I5="OK"),"Solid",IF(B5<=4,"Poor","Standard"))) -> Standard | L5: Blue = hardcoded assumption (chosen by me, not from the dataset)
A6: ='2_Clean_Data'!A3 -> 2 | B6: =INDEX('2_Clean_Data'!$M$2:$M$1360,MATCH($A6,'2_Clean_Data'!$A$2:$A$1360,0)) -> 5 | C6: =VLOOKUP(B6,$L$12:$N$17,2,FALSE()) -> Average | D6: =INDEX('2_Clean_Data'!$L$2:$L$1360,MATCH($A6,'2_Clean_Data'!$A$2:$A$1360,0)) -> 9.8 | E6: =IF(D6<'3_Summary_Tables'!$C$16,"Low",IF(D6<'3_Summary_Tables'!$C$17,"Medium","High")) -> Low | F6: =INDEX('2_Clean_Data'!$C$2:$C$1360,MATCH($A6,'2_Clean_Data'!$A$2:$A$1360,0)) -> 0.88 | G6: =INDEX('2_Clean_Data'!$H$2:$H$1360,MATCH($A6,'2_Clean_Data'!$A$2:$A$1360,0)) -> 67 | H6: =IF(G6>$M$8,"High",IF(G6>$M$7,"Moderate","Low")) -> Moderate | I6: =IF(F6>$M$6,"Above limit","OK") -> Above limit | J6: =IF(AND(B6>=7,E6="High"),"Premium",IF(AND(B6>=6,I6="OK"),"Solid",IF(B6<=4,"Poor","Standard"))) -> Standard | L6: Volatile acidity limit (g/dm3) | M6: 0.7
A7: ='2_Clean_Data'!A4 -> 3 | B7: =INDEX('2_Clean_Data'!$M$2:$M$1360,MATCH($A7,'2_Clean_Data'!$A$2:$A$1360,0)) -> 5 | C7: =VLOOKUP(B7,$L$12:$N$17,2,FALSE()) -> Average | D7: =INDEX('2_Clean_Data'!$L$2:$L$1360,MATCH($A7,'2_Clean_Data'!$A$2:$A$1360,0)) -> 9.8 | E7: =IF(D7<'3_Summary_Tables'!$C$16,"Low",IF(D7<'3_Summary_Tables'!$C$17,"Medium","High")) -> Low | F7: =INDEX('2_Clean_Data'!$C$2:$C$1360,MATCH($A7,'2_Clean_Data'!$A$2:$A$1360,0)) -> 0.76 | G7: =INDEX('2_Clean_Data'!$H$2:$H$1360,MATCH($A7,'2_Clean_Data'!$A$2:$A$1360,0)) -> 54 | H7: =IF(G7>$M$8,"High",IF(G7>$M$7,"Moderate","Low")) -> Moderate | I7: =IF(F7>$M$6,"Above limit","OK") -> Above limit | J7: =IF(AND(B7>=7,E7="High"),"Premium",IF(AND(B7>=6,I7="OK"),"Solid",IF(B7<=4,"Poor","Standard"))) -> Standard | L7: Total SO2 moderate above (mg/dm3) | M7: 50
A8: ='2_Clean_Data'!A5 -> 4 | B8: =INDEX('2_Clean_Data'!$M$2:$M$1360,MATCH($A8,'2_Clean_Data'!$A$2:$A$1360,0)) -> 6 | C8: =VLOOKUP(B8,$L$12:$N$17,2,FALSE()) -> Above Average | D8: =INDEX('2_Clean_Data'!$L$2:$L$1360,MATCH($A8,'2_Clean_Data'!$A$2:$A$1360,0)) -> 9.8 | E8: =IF(D8<'3_Summary_Tables'!$C$16,"Low",IF(D8<'3_Summary_Tables'!$C$17,"Medium","High")) -> Low | F8: =INDEX('2_Clean_Data'!$C$2:$C$1360,MATCH($A8,'2_Clean_Data'!$A$2:$A$1360,0)) -> 0.28 | G8: =INDEX('2_Clean_Data'!$H$2:$H$1360,MATCH($A8,'2_Clean_Data'!$A$2:$A$1360,0)) -> 60 | H8: =IF(G8>$M$8,"High",IF(G8>$M$7,"Moderate","Low")) -> Moderate | I8: =IF(F8>$M$6,"Above limit","OK") -> OK | J8: =IF(AND(B8>=7,E8="High"),"Premium",IF(AND(B8>=6,I8="OK"),"Solid",IF(B8<=4,"Poor","Standard"))) -> Solid | L8: Total SO2 high above (mg/dm3) | M8: 100
A9: ='2_Clean_Data'!A6 -> 5 | B9: =INDEX('2_Clean_Data'!$M$2:$M$1360,MATCH($A9,'2_Clean_Data'!$A$2:$A$1360,0)) -> 5 | C9: =VLOOKUP(B9,$L$12:$N$17,2,FALSE()) -> Average | D9: =INDEX('2_Clean_Data'!$L$2:$L$1360,MATCH($A9,'2_Clean_Data'!$A$2:$A$1360,0)) -> 9.4 | E9: =IF(D9<'3_Summary_Tables'!$C$16,"Low",IF(D9<'3_Summary_Tables'!$C$17,"Medium","High")) -> Low | F9: =INDEX('2_Clean_Data'!$C$2:$C$1360,MATCH($A9,'2_Clean_Data'!$A$2:$A$1360,0)) -> 0.66 | G9: =INDEX('2_Clean_Data'!$H$2:$H$1360,MATCH($A9,'2_Clean_Data'!$A$2:$A$1360,0)) -> 40 | H9: =IF(G9>$M$8,"High",IF(G9>$M$7,"Moderate","Low")) -> Low | I9: =IF(F9>$M$6,"Above limit","OK") -> OK | J9: =IF(AND(B9>=7,E9="High"),"Premium",IF(AND(B9>=6,I9="OK"),"Solid",IF(B9<=4,"Poor","Standard"))) -> Standard
A10: ='2_Clean_Data'!A7 -> 6 | B10: =INDEX('2_Clean_Data'!$M$2:$M$1360,MATCH($A10,'2_Clean_Data'!$A$2:$A$1360,0)) -> 5 | C10: =VLOOKUP(B10,$L$12:$N$17,2,FALSE()) -> Average | D10: =INDEX('2_Clean_Data'!$L$2:$L$1360,MATCH($A10,'2_Clean_Data'!$A$2:$A$1360,0)) -> 9.4 | E10: =IF(D10<'3_Summary_Tables'!$C$16,"Low",IF(D10<'3_Summary_Tables'!$C$17,"Medium","High")) -> Low | F10: =INDEX('2_Clean_Data'!$C$2:$C$1360,MATCH($A10,'2_Clean_Data'!$A$2:$A$1360,0)) -> 0.6 | G10: =INDEX('2_Clean_Data'!$H$2:$H$1360,MATCH($A10,'2_Clean_Data'!$A$2:$A$1360,0)) -> 59 | H10: =IF(G10>$M$8,"High",IF(G10>$M$7,"Moderate","Low")) -> Moderate | I10: =IF(F10>$M$6,"Above limit","OK") -> OK | J10: =IF(AND(B10>=7,E10="High"),"Premium",IF(AND(B10>=6,I10="OK"),"Solid",IF(B10<=4,"Poor","Standard"))) -> Standard | L10: Lookup table: quality score to grade
A11: ='2_Clean_Data'!A8 -> 7 | B11: =INDEX('2_Clean_Data'!$M$2:$M$1360,MATCH($A11,'2_Clean_Data'!$A$2:$A$1360,0)) -> 7 | C11: =VLOOKUP(B11,$L$12:$N$17,2,FALSE()) -> Good | D11: =INDEX('2_Clean_Data'!$L$2:$L$1360,MATCH($A11,'2_Clean_Data'!$A$2:$A$1360,0)) -> 10 | E11: =IF(D11<'3_Summary_Tables'!$C$16,"Low",IF(D11<'3_Summary_Tables'!$C$17,"Medium","High")) -> Medium | F11: =INDEX('2_Clean_Data'!$C$2:$C$1360,MATCH($A11,'2_Clean_Data'!$A$2:$A$1360,0)) -> 0.65 | G11: =INDEX('2_Clean_Data'!$H$2:$H$1360,MATCH($A11,'2_Clean_Data'!$A$2:$A$1360,0)) -> 21 | H11: =IF(G11>$M$8,"High",IF(G11>$M$7,"Moderate","Low")) -> Low | I11: =IF(F11>$M$6,"Above limit","OK") -> OK | J11: =IF(AND(B11>=7,E11="High"),"Premium",IF(AND(B11>=6,I11="OK"),"Solid",IF(B11<=4,"Poor","Standard"))) -> Solid | L11: Quality_Code | M11: Grade | N11: Band
A12: ='2_Clean_Data'!A9 -> 8 | B12: =INDEX('2_Clean_Data'!$M$2:$M$1360,MATCH($A12,'2_Clean_Data'!$A$2:$A$1360,0)) -> 7 | C12: =VLOOKUP(B12,$L$12:$N$17,2,FALSE()) -> Good | D12: =INDEX('2_Clean_Data'!$L$2:$L$1360,MATCH($A12,'2_Clean_Data'!$A$2:$A$1360,0)) -> 9.5 | E12: =IF(D12<'3_Summary_Tables'!$C$16,"Low",IF(D12<'3_Summary_Tables'!$C$17,"Medium","High")) -> Low | F12: =INDEX('2_Clean_Data'!$C$2:$C$1360,MATCH($A12,'2_Clean_Data'!$A$2:$A$1360,0)) -> 0.58 | G12: =INDEX('2_Clean_Data'!$H$2:$H$1360,MATCH($A12,'2_Clean_Data'!$A$2:$A$1360,0)) -> 18 | H12: =IF(G12>$M$8,"High",IF(G12>$M$7,"Moderate","Low")) -> Low | I12: =IF(F12>$M$6,"Above limit","OK") -> OK | J12: =IF(AND(B12>=7,E12="High"),"Premium",IF(AND(B12>=6,I12="OK"),"Solid",IF(B12<=4,"Poor","Standard"))) -> Solid | L12: 3 | M12: Poor | N12: Low
A13: ='2_Clean_Data'!A10 -> 9 | B13: =INDEX('2_Clean_Data'!$M$2:$M$1360,MATCH($A13,'2_Clean_Data'!$A$2:$A$1360,0)) -> 5 | C13: =VLOOKUP(B13,$L$12:$N$17,2,FALSE()) -> Average | D13: =INDEX('2_Clean_Data'!$L$2:$L$1360,MATCH($A13,'2_Clean_Data'!$A$2:$A$1360,0)) -> 10.5 | E13: =IF(D13<'3_Summary_Tables'!$C$16,"Low",IF(D13<'3_Summary_Tables'!$C$17,"Medium","High")) -> Medium | F13: =INDEX('2_Clean_Data'!$C$2:$C$1360,MATCH($A13,'2_Clean_Data'!$A$2:$A$1360,0)) -> 0.5 | G13: =INDEX('2_Clean_Data'!$H$2:$H$1360,MATCH($A13,'2_Clean_Data'!$A$2:$A$1360,0)) -> 102 | H13: =IF(G13>$M$8,"High",IF(G13>$M$7,"Moderate","Low")) -> High | I13: =IF(F13>$M$6,"Above limit","OK") -> OK | J13: =IF(AND(B13>=7,E13="High"),"Premium",IF(AND(B13>=6,I13="OK"),"Solid",IF(B13<=4,"Poor","Standard"))) -> Standard | L13: 4 | M13: Poor | N13: Low
A14: ='2_Clean_Data'!A11 -> 10 | B14: =INDEX('2_Clean_Data'!$M$2:$M$1360,MATCH($A14,'2_Clean_Data'!$A$2:$A$1360,0)) -> 5 | C14: =VLOOKUP(B14,$L$12:$N$17,2,FALSE()) -> Average | D14: =INDEX('2_Clean_Data'!$L$2:$L$1360,MATCH($A14,'2_Clean_Data'!$A$2:$A$1360,0)) -> 9.2 | E14: =IF(D14<'3_Summary_Tables'!$C$16,"Low",IF(D14<'3_Summary_Tables'!$C$17,"Medium","High")) -> Low | F14: =INDEX('2_Clean_Data'!$C$2:$C$1360,MATCH($A14,'2_Clean_Data'!$A$2:$A$1360,0)) -> 0.58 | G14: =INDEX('2_Clean_Data'!$H$2:$H$1360,MATCH($A14,'2_Clean_Data'!$A$2:$A$1360,0)) -> 65 | H14: =IF(G14>$M$8,"High",IF(G14>$M$7,"Moderate","Low")) -> Moderate | I14: =IF(F14>$M$6,"Above limit","OK") -> OK | J14: =IF(AND(B14>=7,E14="High"),"Premium",IF(AND(B14>=6,I14="OK"),"Solid",IF(B14<=4,"Poor","Standard"))) -> Standard | L14: 5 | M14: Average | N14: Medium
A15: ='2_Clean_Data'!A12 -> 11 | B15: =INDEX('2_Clean_Data'!$M$2:$M$1360,MATCH($A15,'2_Clean_Data'!$A$2:$A$1360,0)) -> 5 | C15: =VLOOKUP(B15,$L$12:$N$17,2,FALSE()) -> Average | D15: =INDEX('2_Clean_Data'!$L$2:$L$1360,MATCH($A15,'2_Clean_Data'!$A$2:$A$1360,0)) -> 9.9 | E15: =IF(D15<'3_Summary_Tables'!$C$16,"Low",IF(D15<'3_Summary_Tables'!$C$17,"Medium","High")) -> Low | F15: =INDEX('2_Clean_Data'!$C$2:$C$1360,MATCH($A15,'2_Clean_Data'!$A$2:$A$1360,0)) -> 0.615 | G15: =INDEX('2_Clean_Data'!$H$2:$H$1360,MATCH($A15,'2_Clean_Data'!$A$2:$A$1360,0)) -> 59 | H15: =IF(G15>$M$8,"High",IF(G15>$M$7,"Moderate","Low")) -> Moderate | I15: =IF(F15>$M$6,"Above limit","OK") -> OK | J15: =IF(AND(B15>=7,E15="High"),"Premium",IF(AND(B15>=6,I15="OK"),"Solid",IF(B15<=4,"Poor","Standard"))) -> Standard | L15: 6 | M15: Above Average | N15: Medium
A16: ='2_Clean_Data'!A13 -> 12 | B16: =INDEX('2_Clean_Data'!$M$2:$M$1360,MATCH($A16,'2_Clean_Data'!$A$2:$A$1360,0)) -> 5 | C16: =VLOOKUP(B16,$L$12:$N$17,2,FALSE()) -> Average | D16: =INDEX('2_Clean_Data'!$L$2:$L$1360,MATCH($A16,'2_Clean_Data'!$A$2:$A$1360,0)) -> 9.1 | E16: =IF(D16<'3_Summary_Tables'!$C$16,"Low",IF(D16<'3_Summary_Tables'!$C$17,"Medium","High")) -> Low | F16: =INDEX('2_Clean_Data'!$C$2:$C$1360,MATCH($A16,'2_Clean_Data'!$A$2:$A$1360,0)) -> 0.61 | G16: =INDEX('2_Clean_Data'!$H$2:$H$1360,MATCH($A16,'2_Clean_Data'!$A$2:$A$1360,0)) -> 29 | H16: =IF(G16>$M$8,"High",IF(G16>$M$7,"Moderate","Low")) -> Low | I16: =IF(F16>$M$6,"Above limit","OK") -> OK | J16: =IF(AND(B16>=7,E16="High"),"Premium",IF(AND(B16>=6,I16="OK"),"Solid",IF(B16<=4,"Poor","Standard"))) -> Standard | L16: 7 | M16: Good | N16: High
A17: ='2_Clean_Data'!A14 -> 13 | B17: =INDEX('2_Clean_Data'!$M$2:$M$1360,MATCH($A17,'2_Clean_Data'!$A$2:$A$1360,0)) -> 5 | C17: =VLOOKUP(B17,$L$12:$N$17,2,FALSE()) -> Average | D17: =INDEX('2_Clean_Data'!$L$2:$L$1360,MATCH($A17,'2_Clean_Data'!$A$2:$A$1360,0)) -> 9.2 | E17: =IF(D17<'3_Summary_Tables'!$C$16,"Low",IF(D17<'3_Summary_Tables'!$C$17,"Medium","High")) -> Low | F17: =INDEX('2_Clean_Data'!$C$2:$C$1360,MATCH($A17,'2_Clean_Data'!$A$2:$A$1360,0)) -> 0.62 | G17: =INDEX('2_Clean_Data'!$H$2:$H$1360,MATCH($A17,'2_Clean_Data'!$A$2:$A$1360,0)) -> 145 | H17: =IF(G17>$M$8,"High",IF(G17>$M$7,"Moderate","Low")) -> High | I17: =IF(F17>$M$6,"Above limit","OK") -> OK | J17: =IF(AND(B17>=7,E17="High"),"Premium",IF(AND(B17>=6,I17="OK"),"Solid",IF(B17<=4,"Poor","Standard"))) -> Standard | L17: 8 | M17: Excellent | N17: High
A18: ='2_Clean_Data'!A15 -> 14 | B18: =INDEX('2_Clean_Data'!$M$2:$M$1360,MATCH($A18,'2_Clean_Data'!$A$2:$A$1360,0)) -> 5 | C18: =VLOOKUP(B18,$L$12:$N$17,2,FALSE()) -> Average | D18: =INDEX('2_Clean_Data'!$L$2:$L$1360,MATCH($A18,'2_Clean_Data'!$A$2:$A$1360,0)) -> 9.2 | E18: =IF(D18<'3_Summary_Tables'!$C$16,"Low",IF(D18<'3_Summary_Tables'!$C$17,"Medium","High")) -> Low | F18: =INDEX('2_Clean_Data'!$C$2:$C$1360,MATCH($A18,'2_Clean_Data'!$A$2:$A$1360,0)) -> 0.62 | G18: =INDEX('2_Clean_Data'!$H$2:$H$1360,MATCH($A18,'2_Clean_Data'!$A$2:$A$1360,0)) -> 148 | H18: =IF(G18>$M$8,"High",IF(G18>$M$7,"Moderate","Low")) -> High | I18: =IF(F18>$M$6,"Above limit","OK") -> OK | J18: =IF(AND(B18>=7,E18="High"),"Premium",IF(AND(B18>=6,I18="OK"),"Solid",IF(B18<=4,"Poor","Standard"))) -> Standard
A19: ='2_Clean_Data'!A16 -> 15 | B19: =INDEX('2_Clean_Data'!$M$2:$M$1360,MATCH($A19,'2_Clean_Data'!$A$2:$A$1360,0)) -> 7 | C19: =VLOOKUP(B19,$L$12:$N$17,2,FALSE()) -> Good | D19: =INDEX('2_Clean_Data'!$L$2:$L$1360,MATCH($A19,'2_Clean_Data'!$A$2:$A$1360,0)) -> 10.5 | E19: =IF(D19<'3_Summary_Tables'!$C$16,"Low",IF(D19<'3_Summary_Tables'!$C$17,"Medium","High")) -> Medium | F19: =INDEX('2_Clean_Data'!$C$2:$C$1360,MATCH($A19,'2_Clean_Data'!$A$2:$A$1360,0)) -> 0.28 | G19: =INDEX('2_Clean_Data'!$H$2:$H$1360,MATCH($A19,'2_Clean_Data'!$A$2:$A$1360,0)) -> 103 | H19: =IF(G19>$M$8,"High",IF(G19>$M$7,"Moderate","Low")) -> High | I19: =IF(F19>$M$6,"Above limit","OK") -> OK | J19: =IF(AND(B19>=7,E19="High"),"Premium",IF(AND(B19>=6,I19="OK"),"Solid",IF(B19<=4,"Poor","Standard"))) -> Solid
A20: ='2_Clean_Data'!A17 -> 16 | B20: =INDEX('2_Clean_Data'!$M$2:$M$1360,MATCH($A20,'2_Clean_Data'!$A$2:$A$1360,0)) -> 5 | C20: =VLOOKUP(B20,$L$12:$N$17,2,FALSE()) -> Average | D20: =INDEX('2_Clean_Data'!$L$2:$L$1360,MATCH($A20,'2_Clean_Data'!$A$2:$A$1360,0)) -> 9.3 | E20: =IF(D20<'3_Summary_Tables'!$C$16,"Low",IF(D20<'3_Summary_Tables'!$C$17,"Medium","High")) -> Low | F20: =INDEX('2_Clean_Data'!$C$2:$C$1360,MATCH($A20,'2_Clean_Data'!$A$2:$A$1360,0)) -> 0.56 | G20: =INDEX('2_Clean_Data'!$H$2:$H$1360,MATCH($A20,'2_Clean_Data'!$A$2:$A$1360,0)) -> 56 | H20: =IF(G20>$M$8,"High",IF(G20>$M$7,"Moderate","Low")) -> Moderate | I20: =IF(F20>$M$6,"Above limit","OK") -> OK | J20: =IF(AND(B20>=7,E20="High"),"Premium",IF(AND(B20>=6,I20="OK"),"Solid",IF(B20<=4,"Poor","Standard"))) -> Standard | L20: Wine finder
A21: ='2_Clean_Data'!A18 -> 17 | B21: =INDEX('2_Clean_Data'!$M$2:$M$1360,MATCH($A21,'2_Clean_Data'!$A$2:$A$1360,0)) -> 4 | C21: =VLOOKUP(B21,$L$12:$N$17,2,FALSE()) -> Poor | D21: =INDEX('2_Clean_Data'!$L$2:$L$1360,MATCH($A21,'2_Clean_Data'!$A$2:$A$1360,0)) -> 9 | E21: =IF(D21<'3_Summary_Tables'!$C$16,"Low",IF(D21<'3_Summary_Tables'!$C$17,"Medium","High")) -> Low | F21: =INDEX('2_Clean_Data'!$C$2:$C$1360,MATCH($A21,'2_Clean_Data'!$A$2:$A$1360,0)) -> 0.59 | G21: =INDEX('2_Clean_Data'!$H$2:$H$1360,MATCH($A21,'2_Clean_Data'!$A$2:$A$1360,0)) -> 29 | H21: =IF(G21>$M$8,"High",IF(G21>$M$7,"Moderate","Low")) -> Low | I21: =IF(F21>$M$6,"Above limit","OK") -> OK | J21: =IF(AND(B21>=7,E21="High"),"Premium",IF(AND(B21>=6,I21="OK"),"Solid",IF(B21<=4,"Poor","Standard"))) -> Poor | L21: Enter Wine_ID (1-1359) | M21: 25
A22: ='2_Clean_Data'!A19 -> 18 | B22: =INDEX('2_Clean_Data'!$M$2:$M$1360,MATCH($A22,'2_Clean_Data'!$A$2:$A$1360,0)) -> 6 | C22: =VLOOKUP(B22,$L$12:$N$17,2,FALSE()) -> Above Average | D22: =INDEX('2_Clean_Data'!$L$2:$L$1360,MATCH($A22,'2_Clean_Data'!$A$2:$A$1360,0)) -> 9.2 | E22: =IF(D22<'3_Summary_Tables'!$C$16,"Low",IF(D22<'3_Summary_Tables'!$C$17,"Medium","High")) -> Low | F22: =INDEX('2_Clean_Data'!$C$2:$C$1360,MATCH($A22,'2_Clean_Data'!$A$2:$A$1360,0)) -> 0.32 | G22: =INDEX('2_Clean_Data'!$H$2:$H$1360,MATCH($A22,'2_Clean_Data'!$A$2:$A$1360,0)) -> 56 | H22: =IF(G22>$M$8,"High",IF(G22>$M$7,"Moderate","Low")) -> Moderate | I22: =IF(F22>$M$6,"Above limit","OK") -> OK | J22: =IF(AND(B22>=7,E22="High"),"Premium",IF(AND(B22>=6,I22="OK"),"Solid",IF(B22<=4,"Poor","Standard"))) -> Solid | L22: Field | M22: Result | N22: Method
A23: ='2_Clean_Data'!A20 -> 19 | B23: =INDEX('2_Clean_Data'!$M$2:$M$1360,MATCH($A23,'2_Clean_Data'!$A$2:$A$1360,0)) -> 6 | C23: =VLOOKUP(B23,$L$12:$N$17,2,FALSE()) -> Above Average | D23: =INDEX('2_Clean_Data'!$L$2:$L$1360,MATCH($A23,'2_Clean_Data'!$A$2:$A$1360,0)) -> 9.4 | E23: =IF(D23<'3_Summary_Tables'!$C$16,"Low",IF(D23<'3_Summary_Tables'!$C$17,"Medium","High")) -> Low | F23: =INDEX('2_Clean_Data'!$C$2:$C$1360,MATCH($A23,'2_Clean_Data'!$A$2:$A$1360,0)) -> 0.22 | G23: =INDEX('2_Clean_Data'!$H$2:$H$1360,MATCH($A23,'2_Clean_Data'!$A$2:$A$1360,0)) -> 60 | H23: =IF(G23>$M$8,"High",IF(G23>$M$7,"Moderate","Low")) -> Moderate | I23: =IF(F23>$M$6,"Above limit","OK") -> OK | J23: =IF(AND(B23>=7,E23="High"),"Premium",IF(AND(B23>=6,I23="OK"),"Solid",IF(B23<=4,"Poor","Standard"))) -> Solid | L23: Quality | M23: =IFERROR(VLOOKUP($M$21,'2_Clean_Data'!$A$2:$M$1360,13,FALSE()),"Not found") -> 5 | N23: VLOOKUP
A24: ='2_Clean_Data'!A21 -> 20 | B24: =INDEX('2_Clean_Data'!$M$2:$M$1360,MATCH($A24,'2_Clean_Data'!$A$2:$A$1360,0)) -> 5 | C24: =VLOOKUP(B24,$L$12:$N$17,2,FALSE()) -> Average | D24: =INDEX('2_Clean_Data'!$L$2:$L$1360,MATCH($A24,'2_Clean_Data'!$A$2:$A$1360,0)) -> 9.7 | E24: =IF(D24<'3_Summary_Tables'!$C$16,"Low",IF(D24<'3_Summary_Tables'!$C$17,"Medium","High")) -> Low | F24: =INDEX('2_Clean_Data'!$C$2:$C$1360,MATCH($A24,'2_Clean_Data'!$A$2:$A$1360,0)) -> 0.39 | G24: =INDEX('2_Clean_Data'!$H$2:$H$1360,MATCH($A24,'2_Clean_Data'!$A$2:$A$1360,0)) -> 71 | H24: =IF(G24>$M$8,"High",IF(G24>$M$7,"Moderate","Low")) -> Moderate | I24: =IF(F24>$M$6,"Above limit","OK") -> OK | J24: =IF(AND(B24>=7,E24="High"),"Premium",IF(AND(B24>=6,I24="OK"),"Solid",IF(B24<=4,"Poor","Standard"))) -> Standard | L24: Alcohol (%) | M24: =IFERROR(INDEX('2_Clean_Data'!$L$2:$L$1360,MATCH($M$21,'2_Clean_Data'!$A$2:$A$1360,0)),"Not found") -> 9.5 | N24: INDEX-MATCH
A25: ='2_Clean_Data'!A22 -> 21 | B25: =INDEX('2_Clean_Data'!$M$2:$M$1360,MATCH($A25,'2_Clean_Data'!$A$2:$A$1360,0)) -> 5 | C25: =VLOOKUP(B25,$L$12:$N$17,2,FALSE()) -> Average | D25: =INDEX('2_Clean_Data'!$L$2:$L$1360,MATCH($A25,'2_Clean_Data'!$A$2:$A$1360,0)) -> 9.5 | E25: =IF(D25<'3_Summary_Tables'!$C$16,"Low",IF(D25<'3_Summary_Tables'!$C$17,"Medium","High")) -> Low | F25: =INDEX('2_Clean_Data'!$C$2:$C$1360,MATCH($A25,'2_Clean_Data'!$A$2:$A$1360,0)) -> 0.43 | G25: =INDEX('2_Clean_Data'!$H$2:$H$1360,MATCH($A25,'2_Clean_Data'!$A$2:$A$1360,0)) -> 37 | H25: =IF(G25>$M$8,"High",IF(G25>$M$7,"Moderate","Low")) -> Low | I25: =IF(F25>$M$6,"Above limit","OK") -> OK | J25: =IF(AND(B25>=7,E25="High"),"Premium",IF(AND(B25>=6,I25="OK"),"Solid",IF(B25<=4,"Poor","Standard"))) -> Standard | L25: pH | M25: =IFERROR(INDEX('2_Clean_Data'!$J$2:$J$1360,MATCH($M$21,'2_Clean_Data'!$A$2:$A$1360,0)),"Not found") -> 3.28 | N25: INDEX-MATCH
A26: ='2_Clean_Data'!A23 -> 22 | B26: =INDEX('2_Clean_Data'!$M$2:$M$1360,MATCH($A26,'2_Clean_Data'!$A$2:$A$1360,0)) -> 5 | C26: =VLOOKUP(B26,$L$12:$N$17,2,FALSE()) -> Average | D26: =INDEX('2_Clean_Data'!$L$2:$L$1360,MATCH($A26,'2_Clean_Data'!$A$2:$A$1360,0)) -> 9.4 | E26: =IF(D26<'3_Summary_Tables'!$C$16,"Low",IF(D26<'3_Summary_Tables'!$C$17,"Medium","High")) -> Low | F26: =INDEX('2_Clean_Data'!$C$2:$C$1360,MATCH($A26,'2_Clean_Data'!$A$2:$A$1360,0)) -> 0.49 | G26: =INDEX('2_Clean_Data'!$H$2:$H$1360,MATCH($A26,'2_Clean_Data'!$A$2:$A$1360,0)) -> 67 | H26: =IF(G26>$M$8,"High",IF(G26>$M$7,"Moderate","Low")) -> Moderate | I26: =IF(F26>$M$6,"Above limit","OK") -> OK | J26: =IF(AND(B26>=7,E26="High"),"Premium",IF(AND(B26>=6,I26="OK"),"Solid",IF(B26<=4,"Poor","Standard"))) -> Standard | L26: Grade | M26: =IFERROR(VLOOKUP(M23,$L$12:$N$17,2,FALSE()),"Not found") -> Average | N26: VLOOKUP on lookup table
A27: ='2_Clean_Data'!A24 -> 23 | B27: =INDEX('2_Clean_Data'!$M$2:$M$1360,MATCH($A27,'2_Clean_Data'!$A$2:$A$1360,0)) -> 6 | C27: =VLOOKUP(B27,$L$12:$N$17,2,FALSE()) -> Above Average | D27: =INDEX('2_Clean_Data'!$L$2:$L$1360,MATCH($A27,'2_Clean_Data'!$A$2:$A$1360,0)) -> 9.7 | E27: =IF(D27<'3_Summary_Tables'!$C$16,"Low",IF(D27<'3_Summary_Tables'!$C$17,"Medium","High")) -> Low | F27: =INDEX('2_Clean_Data'!$C$2:$C$1360,MATCH($A27,'2_Clean_Data'!$A$2:$A$1360,0)) -> 0.4 | G27: =INDEX('2_Clean_Data'!$H$2:$H$1360,MATCH($A27,'2_Clean_Data'!$A$2:$A$1360,0)) -> 40 | H27: =IF(G27>$M$8,"High",IF(G27>$M$7,"Moderate","Low")) -> Low | I27: =IF(F27>$M$6,"Above limit","OK") -> OK | J27: =IF(AND(B27>=7,E27="High"),"Premium",IF(AND(B27>=6,I27="OK"),"Solid",IF(B27<=4,"Poor","Standard"))) -> Solid | L27: Profile | M27: =IFERROR(INDEX($J$5:$J$1363,MATCH($M$21,$A$5:$A$1363,0)),"Not found") -> Standard | N27: INDEX-MATCH on formula column
A28: ='2_Clean_Data'!A25 -> 24 | B28: =INDEX('2_Clean_Data'!$M$2:$M$1360,MATCH($A28,'2_Clean_Data'!$A$2:$A$1360,0)) -> 5 | C28: =VLOOKUP(B28,$L$12:$N$17,2,FALSE()) -> Average | D28: =INDEX('2_Clean_Data'!$L$2:$L$1360,MATCH($A28,'2_Clean_Data'!$A$2:$A$1360,0)) -> 9.3 | E28: =IF(D28<'3_Summary_Tables'!$C$16,"Low",IF(D28<'3_Summary_Tables'!$C$17,"Medium","High")) -> Low | F28: =INDEX('2_Clean_Data'!$C$2:$C$1360,MATCH($A28,'2_Clean_Data'!$A$2:$A$1360,0)) -> 0.39 | G28: =INDEX('2_Clean_Data'!$H$2:$H$1360,MATCH($A28,'2_Clean_Data'!$A$2:$A$1360,0)) -> 23 | H28: =IF(G28>$M$8,"High",IF(G28>$M$7,"Moderate","Low")) -> Low | I28: =IF(F28>$M$6,"Above limit","OK") -> OK | J28: =IF(AND(B28>=7,E28="High"),"Premium",IF(AND(B28>=6,I28="OK"),"Solid",IF(B28<=4,"Poor","Standard"))) -> Standard
A29: ='2_Clean_Data'!A26 -> 25 | B29: =INDEX('2_Clean_Data'!$M$2:$M$1360,MATCH($A29,'2_Clean_Data'!$A$2:$A$1360,0)) -> 5 | C29: =VLOOKUP(B29,$L$12:$N$17,2,FALSE()) -> Average | D29: =INDEX('2_Clean_Data'!$L$2:$L$1360,MATCH($A29,'2_Clean_Data'!$A$2:$A$1360,0)) -> 9.5 | E29: =IF(D29<'3_Summary_Tables'!$C$16,"Low",IF(D29<'3_Summary_Tables'!$C$17,"Medium","High")) -> Low | F29: =INDEX('2_Clean_Data'!$C$2:$C$1360,MATCH($A29,'2_Clean_Data'!$A$2:$A$1360,0)) -> 0.41 | G29: =INDEX('2_Clean_Data'!$H$2:$H$1360,MATCH($A29,'2_Clean_Data'!$A$2:$A$1360,0)) -> 11 | H29: =IF(G29>$M$8,"High",IF(G29>$M$7,"Moderate","Low")) -> Low | I29: =IF(F29>$M$6,"Above limit","OK") -> OK | J29: =IF(AND(B29>=7,E29="High"),"Premium",IF(AND(B29>=6,I29="OK"),"Solid",IF(B29<=4,"Poor","Standard"))) -> Standard
A30: ='2_Clean_Data'!A27 -> 26 | B30: =INDEX('2_Clean_Data'!$M$2:$M$1360,MATCH($A30,'2_Clean_Data'!$A$2:$A$1360,0)) -> 5 | C30: =VLOOKUP(B30,$L$12:$N$17,2,FALSE()) -> Average | D30: =INDEX('2_Clean_Data'!$L$2:$L$1360,MATCH($A30,'2_Clean_Data'!$A$2:$A$1360,0)) -> 9.4 | E30: =IF(D30<'3_Summary_Tables'!$C$16,"Low",IF(D30<'3_Summary_Tables'!$C$17,"Medium","High")) -> Low | F30: =INDEX('2_Clean_Data'!$C$2:$C$1360,MATCH($A30,'2_Clean_Data'!$A$2:$A$1360,0)) -> 0.71 | G30: =INDEX('2_Clean_Data'!$H$2:$H$1360,MATCH($A30,'2_Clean_Data'!$A$2:$A$1360,0)) -> 35 | H30: =IF(G30>$M$8,"High",IF(G30>$M$7,"Moderate","Low")) -> Low | I30: =IF(F30>$M$6,"Above limit","OK") -> Above limit | J30: =IF(AND(B30>=7,E30="High"),"Premium",IF(AND(B30>=6,I30="OK"),"Solid",IF(B30<=4,"Poor","Standard"))) -> Standard
A31: ='2_Clean_Data'!A28 -> 27 | B31: =INDEX('2_Clean_Data'!$M$2:$M$1360,MATCH($A31,'2_Clean_Data'!$A$2:$A$1360,0)) -> 6 | C31: =VLOOKUP(B31,$L$12:$N$17,2,FALSE()) -> Above Average | D31: =INDEX('2_Clean_Data'!$L$2:$L$1360,MATCH($A31,'2_Clean_Data'!$A$2:$A$1360,0)) -> 9.8 | E31: =IF(D31<'3_Summary_Tables'!$C$16,"Low",IF(D31<'3_Summary_Tables'!$C$17,"Medium","High")) -> Low | F31: =INDEX('2_Clean_Data'!$C$2:$C$1360,MATCH($A31,'2_Clean_Data'!$A$2:$A$1360,0)) -> 0.645 | G31: =INDEX('2_Clean_Data'!$H$2:$H$1360,MATCH($A31,'2_Clean_Data'!$A$2:$A$1360,0)) -> 16 | H31: =IF(G31>$M$8,"High",IF(G31>$M$7,"Moderate","Low")) -> Low | I31: =IF(F31>$M$6,"Above limit","OK") -> OK | J31: =IF(AND(B31>=7,E31="High"),"Premium",IF(AND(B31>=6,I31="OK"),"Solid",IF(B31<=4,"Poor","Standard"))) -> Solid
A32: ='2_Clean_Data'!A29 -> 28 | B32: =INDEX('2_Clean_Data'!$M$2:$M$1360,MATCH($A32,'2_Clean_Data'!$A$2:$A$1360,0)) -> 5 | C32: =VLOOKUP(B32,$L$12:$N$17,2,FALSE()) -> Average | D32: =INDEX('2_Clean_Data'!$L$2:$L$1360,MATCH($A32,'2_Clean_Data'!$A$2:$A$1360,0)) -> 10.1 | E32: =IF(D32<'3_Summary_Tables'!$C$16,"Low",IF(D32<'3_Summary_Tables'!$C$17,"Medium","High")) -> Medium | F32: =INDEX('2_Clean_Data'!$C$2:$C$1360,MATCH($A32,'2_Clean_Data'!$A$2:$A$1360,0)) -> 0.675 | G32: =INDEX('2_Clean_Data'!$H$2:$H$1360,MATCH($A32,'2_Clean_Data'!$A$2:$A$1360,0)) -> 82 | H32: =IF(G32>$M$8,"High",IF(G32>$M$7,"Moderate","Low")) -> Moderate | I32: =IF(F32>$M$6,"Above limit","OK") -> OK | J32: =IF(AND(B32>=7,E32="High"),"Premium",IF(AND(B32>=6,I32="OK"),"Solid",IF(B32<=4,"Poor","Standard"))) -> Standard
A33: ='2_Clean_Data'!A30 -> 29 | B33: =INDEX('2_Clean_Data'!$M$2:$M$1360,MATCH($A33,'2_Clean_Data'!$A$2:$A$1360,0)) -> 6 | C33: =VLOOKUP(B33,$L$12:$N$17,2,FALSE()) -> Above Average | D33: =INDEX('2_Clean_Data'!$L$2:$L$1360,MATCH($A33,'2_Clean_Data'!$A$2:$A$1360,0)) -> 10.6 | E33: =IF(D33<'3_Summary_Tables'!$C$16,"Low",IF(D33<'3_Summary_Tables'!$C$17,"Medium","High")) -> Medium | F33: =INDEX('2_Clean_Data'!$C$2:$C$1360,MATCH($A33,'2_Clean_Data'!$A$2:$A$1360,0)) -> 0.685 | G33: =INDEX('2_Clean_Data'!$H$2:$H$1360,MATCH($A33,'2_Clean_Data'!$A$2:$A$1360,0)) -> 37 | H33: =IF(G33>$M$8,"High",IF(G33>$M$7,"Moderate","Low")) -> Low | I33: =IF(F33>$M$6,"Above limit","OK") -> OK | J33: =IF(AND(B33>=7,E33="High"),"Premium",IF(AND(B33>=6,I33="OK"),"Solid",IF(B33<=4,"Poor","Standard"))) -> Solid
A34: ='2_Clean_Data'!A31 -> 30 | B34: =INDEX('2_Clean_Data'!$M$2:$M$1360,MATCH($A34,'2_Clean_Data'!$A$2:$A$1360,0)) -> 5 | C34: =VLOOKUP(B34,$L$12:$N$17,2,FALSE()) -> Average | D34: =INDEX('2_Clean_Data'!$L$2:$L$1360,MATCH($A34,'2_Clean_Data'!$A$2:$A$1360,0)) -> 9.8 | E34: =IF(D34<'3_Summary_Tables'!$C$16,"Low",IF(D34<'3_Summary_Tables'!$C$17,"Medium","High")) -> Low | F34: =INDEX('2_Clean_Data'!$C$2:$C$1360,MATCH($A34,'2_Clean_Data'!$A$2:$A$1360,0)) -> 0.655 | G34: =INDEX('2_Clean_Data'!$H$2:$H$1360,MATCH($A34,'2_Clean_Data'!$A$2:$A$1360,0)) -> 113 | H34: =IF(G34>$M$8,"High",IF(G34>$M$7,"Moderate","Low")) -> High | I34: =IF(F34>$M$6,"Above limit","OK") -> OK | J34: =IF(AND(B34>=7,E34="High"),"Premium",IF(AND(B34>=6,I34="OK"),"Solid",IF(B34<=4,"Poor","Standard"))) -> Standard
A35: ='2_Clean_Data'!A32 -> 31 | B35: =INDEX('2_Clean_Data'!$M$2:$M$1360,MATCH($A35,'2_Clean_Data'!$A$2:$A$1360,0)) -> 6 | C35: =VLOOKUP(B35,$L$12:$N$17,2,FALSE()) -> Above Average | D35: =INDEX('2_Clean_Data'!$L$2:$L$1360,MATCH($A35,'2_Clean_Data'!$A$2:$A$1360,0)) -> 9.4 | E35: =IF(D35<'3_Summary_Tables'!$C$16,"Low",IF(D35<'3_Summary_Tables'!$C$17,"Medium","High")) -> Low | F35: =INDEX('2_Clean_Data'!$C$2:$C$1360,MATCH($A35,'2_Clean_Data'!$A$2:$A$1360,0)) -> 0.605 | G35: =INDEX('2_Clean_Data'!$H$2:$H$1360,MATCH($A35,'2_Clean_Data'!$A$2:$A$1360,0)) -> 83 | H35: =IF(G35>$M$8,"High",IF(G35>$M$7,"Moderate","Low")) -> Moderate | I35: =IF(F35>$M$6,"Above limit","OK") -> OK | J35: =IF(AND(B35>=7,E35="High"),"Premium",IF(AND(B35>=6,I35="OK"),"Solid",IF(B35<=4,"Poor","Standard"))) -> Solid
A36: ='2_Clean_Data'!A33 -> 32 | B36: =INDEX('2_Clean_Data'!$M$2:$M$1360,MATCH($A36,'2_Clean_Data'!$A$2:$A$1360,0)) -> 5 | C36: =VLOOKUP(B36,$L$12:$N$17,2,FALSE()) -> Average | D36: =INDEX('2_Clean_Data'!$L$2:$L$1360,MATCH($A36,'2_Clean_Data'!$A$2:$A$1360,0)) -> 9.2 | E36: =IF(D36<'3_Summary_Tables'!$C$16,"Low",IF(D36<'3_Summary_Tables'!$C$17,"Medium","High")) -> Low | F36: =INDEX('2_Clean_Data'!$C$2:$C$1360,MATCH($A36,'2_Clean_Data'!$A$2:$A$1360,0)) -> 0.32 | G36: =INDEX('2_Clean_Data'!$H$2:$H$1360,MATCH($A36,'2_Clean_Data'!$A$2:$A$1360,0)) -> 50 | H36: =IF(G36>$M$8,"High",IF(G36>$M$7,"Moderate","Low")) -> Low | I36: =IF(F36>$M$6,"Above limit","OK") -> OK | J36: =IF(AND(B36>=7,E36="High"),"Premium",IF(AND(B36>=6,I36="OK"),"Solid",IF(B36<=4,"Poor","Standard"))) -> Standard
A37: ='2_Clean_Data'!A34 -> 33 | B37: =INDEX('2_Clean_Data'!$M$2:$M$1360,MATCH($A37,'2_Clean_Data'!$A$2:$A$1360,0)) -> 6 | C37: =VLOOKUP(B37,$L$12:$N$17,2,FALSE()) -> Above Average | D37: =INDEX('2_Clean_Data'!$L$2:$L$1360,MATCH($A37,'2_Clean_Data'!$A$2:$A$1360,0)) -> 9.6 | E37: =IF(D37<'3_Summary_Tables'!$C$16,"Low",IF(D37<'3_Summary_Tables'!$C$17,"Medium","High")) -> Low | F37: =INDEX('2_Clean_Data'!$C$2:$C$1360,MATCH($A37,'2_Clean_Data'!$A$2:$A$1360,0)) -> 0.645 | G37: =INDEX('2_Clean_Data'!$H$2:$H$1360,MATCH($A37,'2_Clean_Data'!$A$2:$A$1360,0)) -> 18 | H37: =IF(G37>$M$8,"High",IF(G37>$M$7,"Moderate","Low")) -> Low | I37: =IF(F37>$M$6,"Above limit","OK") -> OK | J37: =IF(AND(B37>=7,E37="High"),"Premium",IF(AND(B37>=6,I37="OK"),"Solid",IF(B37<=4,"Poor","Standard"))) -> Solid
A38: ='2_Clean_Data'!A35 -> 34 | B38: =INDEX('2_Clean_Data'!$M$2:$M$1360,MATCH($A38,'2_Clean_Data'!$A$2:$A$1360,0)) -> 6 | C38: =VLOOKUP(B38,$L$12:$N$17,2,FALSE()) -> Above Average | D38: =INDEX('2_Clean_Data'!$L$2:$L$1360,MATCH($A38,'2_Clean_Data'!$A$2:$A$1360,0)) -> 10.8 | E38: =IF(D38<'3_Summary_Tables'!$C$16,"Low",IF(D38<'3_Summary_Tables'!$C$17,"Medium","High")) -> Medium | F38: =INDEX('2_Clean_Data'!$C$2:$C$1360,MATCH($A38,'2_Clean_Data'!$A$2:$A$1360,0)) -> 0.6 | G38: =INDEX('2_Clean_Data'!$H$2:$H$1360,MATCH($A38,'2_Clean_Data'!$A$2:$A$1360,0)) -> 15 | H38: =IF(G38>$M$8,"High",IF(G38>$M$7,"Moderate","Low")) -> Low | I38: =IF(F38>$M$6,"Above limit","OK") -> OK | J38: =IF(AND(B38>=7,E38="High"),"Premium",IF(AND(B38>=6,I38="OK"),"Solid",IF(B38<=4,"Poor","Standard"))) -> Solid
A39: ='2_Clean_Data'!A36 -> 35 | B39: =INDEX('2_Clean_Data'!$M$2:$M$1360,MATCH($A39,'2_Clean_Data'!$A$2:$A$1360,0)) -> 7 | C39: =VLOOKUP(B39,$L$12:$N$17,2,FALSE()) -> Good | D39: =INDEX('2_Clean_Data'!$L$2:$L$1360,MATCH($A39,'2_Clean_Data'!$A$2:$A$1360,0)) -> 9.7 | E39: =IF(D39<'3_Summary_Tables'!$C$16,"Low",IF(D39<'3_Summary_Tables'!$C$17,"Medium","High")) -> Low | F39: =INDEX('2_Clean_Data'!$C$2:$C$1360,MATCH($A39,'2_Clean_Data'!$A$2:$A$1360,0)) -> 0.38 | G39: =INDEX('2_Clean_Data'!$H$2:$H$1360,MATCH($A39,'2_Clean_Data'!$A$2:$A$1360,0)) -> 30 | H39: =IF(G39>$M$8,"High",IF(G39>$M$7,"Moderate","Low")) -> Low | I39: =IF(F39>$M$6,"Above limit","OK") -> OK | J39: =IF(AND(B39>=7,E39="High"),"Premium",IF(AND(B39>=6,I39="OK"),"Solid",IF(B39<=4,"Poor","Standard"))) -> Solid
... A1363: ='2_Clean_Data'!A1360 -> 1359 | B1363: =INDEX('2_Clean_Data'!$M$2:$M$1360,MATCH($A1363,'2_Clean_Data'!$A$2:$A$1360,0)) -> 6 | C1363: =VLOOKUP(B1363,$L$12:$N$17,2,FALSE()) -> Above Average | D1363: =INDEX('2_Clean_Data'!$L$2:$L$1360,MATCH($A1363,'2_Clean_Data'!$A$2:$A$1360,0)) -> 11 | E1363: =IF(D1363<'3_Summary_Tables'!$C$16,"Low",IF(D1363<'3_Summary_Tables'!$C$17,"Medium","High")) -> Medium | F1363: =INDEX('2_Clean_Data'!$C$2:$C$1360,MATCH($A1363,'2_Clean_Data'!$A$2:$A$1360,0)) -> 0.31 | G1363: =INDEX('2_Clean_Data'!$H$2:$H$1360,MATCH($A1363,'2_Clean_Data'!$A$2:$A$1360,0)) -> 42 | H1363: =IF(G1363>$M$8,"High",IF(G1363>$M$7,"Moderate","Low")) -> Low | I1363: =IF(F1363>$M$6,"Above limit","OK") -> OK | J1363: =IF(AND(B1363>=7,E1363="High"),"Premium",IF(AND(B1363>=6,I1363="OK"),"Solid",IF(B1363<=4,"Poor","Standard"))) -> Solid

Sheet 5_Visualization
A1: Data Visualization
A2: Charts read from 3_Summary_Tables. The heat map below is a live CORREL matrix with conditional formatting.
A3: Correlation matrix (red = positive, blue = negative)
B4: ='2_Clean_Data'!B1 -> Fixed_Acidity | C4: ='2_Clean_Data'!C1 -> Volatile_Acidity | D4: ='2_Clean_Data'!D1 -> Citric_Acid | E4: ='2_Clean_Data'!E1 -> Residual_Sugar | F4: ='2_Clean_Data'!F1 -> Chlorides | G4: ='2_Clean_Data'!G1 -> Free_Sulfur_Dioxide | H4: ='2_Clean_Data'!H1 -> Total_Sulfur_Dioxide | I4: ='2_Clean_Data'!I1 -> Density | ... M4: ='2_Clean_Data'!M1 -> Quality
A5: ='2_Clean_Data'!B1 -> Fixed_Acidity | B5: =CORREL(INDEX(rngData,0,1),INDEX(rngData,0,1)) -> 1 | C5: =CORREL(INDEX(rngData,0,1),INDEX(rngData,0,2)) -> -0.25512446 | D5: =CORREL(INDEX(rngData,0,1),INDEX(rngData,0,3)) -> 0.66743738 | E5: =CORREL(INDEX(rngData,0,1),INDEX(rngData,0,4)) -> 0.11102547 | F5: =CORREL(INDEX(rngData,0,1),INDEX(rngData,0,5)) -> 0.085886247 | G5: =CORREL(INDEX(rngData,0,1),INDEX(rngData,0,6)) -> -0.14058002 | H5: =CORREL(INDEX(rngData,0,1),INDEX(rngData,0,7)) -> -0.1037768 | I5: =CORREL(INDEX(rngData,0,1),INDEX(rngData,0,8)) -> 0.67019502 | J5: =CORREL(INDEX(rngData,0,1),INDEX(rngData,0,9)) -> -0.68668511 | K5: =CORREL(INDEX(rngData,0,1),INDEX(rngData,0,10)) -> 0.19026948 | L5: =CORREL(INDEX(rngData,0,1),INDEX(rngData,0,11)) -> -0.061596149 | M5: =CORREL(INDEX(rngData,0,1),INDEX(rngData,0,12)) -> 0.11902367
A6: ='2_Clean_Data'!C1 -> Volatile_Acidity | B6: =CORREL(INDEX(rngData,0,2),INDEX(rngData,0,1)) -> -0.25512446 | C6: =CORREL(INDEX(rngData,0,2),INDEX(rngData,0,2)) -> 1 | D6: =CORREL(INDEX(rngData,0,2),INDEX(rngData,0,3)) -> -0.55124804 | E6: =CORREL(INDEX(rngData,0,2),INDEX(rngData,0,4)) -> -0.0024488891 | F6: =CORREL(INDEX(rngData,0,2),INDEX(rngData,0,5)) -> 0.05515367 | G6: =CORREL(INDEX(rngData,0,2),INDEX(rngData,0,6)) -> -0.020944843 | H6: =CORREL(INDEX(rngData,0,2),INDEX(rngData,0,7)) -> 0.071701061 | I6: =CORREL(INDEX(rngData,0,2),INDEX(rngData,0,8)) -> 0.023942944 | J6: =CORREL(INDEX(rngData,0,2),INDEX(rngData,0,9)) -> 0.24711113 | K6: =CORREL(INDEX(rngData,0,2),INDEX(rngData,0,10)) -> -0.25694777 | L6: =CORREL(INDEX(rngData,0,2),INDEX(rngData,0,11)) -> -0.19781222 | M6: =CORREL(INDEX(rngData,0,2),INDEX(rngData,0,12)) -> -0.39521369
A7: ='2_Clean_Data'!D1 -> Citric_Acid | B7: =CORREL(INDEX(rngData,0,3),INDEX(rngData,0,1)) -> 0.66743738 | C7: =CORREL(INDEX(rngData,0,3),INDEX(rngData,0,2)) -> -0.55124804 | D7: =CORREL(INDEX(rngData,0,3),INDEX(rngData,0,3)) -> 1 | E7: =CORREL(INDEX(rngData,0,3),INDEX(rngData,0,4)) -> 0.14389179 | F7: =CORREL(INDEX(rngData,0,3),INDEX(rngData,0,5)) -> 0.21019453 | G7: =CORREL(INDEX(rngData,0,3),INDEX(rngData,0,6)) -> -0.048004466 | H7: =CORREL(INDEX(rngData,0,3),INDEX(rngData,0,7)) -> 0.047357609 | I7: =CORREL(INDEX(rngData,0,3),INDEX(rngData,0,8)) -> 0.35796189 | J7: =CORREL(INDEX(rngData,0,3),INDEX(rngData,0,9)) -> -0.55030976 | K7: =CORREL(INDEX(rngData,0,3),INDEX(rngData,0,10)) -> 0.32606233 | L7: =CORREL(INDEX(rngData,0,3),INDEX(rngData,0,11)) -> 0.10510809 | M7: =CORREL(INDEX(rngData,0,3),INDEX(rngData,0,12)) -> 0.22805746
A8: ='2_Clean_Data'!E1 -> Residual_Sugar | B8: =CORREL(INDEX(rngData,0,4),INDEX(rngData,0,1)) -> 0.11102547 | C8: =CORREL(INDEX(rngData,0,4),INDEX(rngData,0,2)) -> -0.0024488891 | D8: =CORREL(INDEX(rngData,0,4),INDEX(rngData,0,3)) -> 0.14389179 | E8: =CORREL(INDEX(rngData,0,4),INDEX(rngData,0,4)) -> 1 | F8: =CORREL(INDEX(rngData,0,4),INDEX(rngData,0,5)) -> 0.026656141 | G8: =CORREL(INDEX(rngData,0,4),INDEX(rngData,0,6)) -> 0.16052715 | H8: =CORREL(INDEX(rngData,0,4),INDEX(rngData,0,7)) -> 0.20103849 | I8: =CORREL(INDEX(rngData,0,4),INDEX(rngData,0,8)) -> 0.32452248 | J8: =CORREL(INDEX(rngData,0,4),INDEX(rngData,0,9)) -> -0.083143484 | K8: =CORREL(INDEX(rngData,0,4),INDEX(rngData,0,10)) -> -0.011836572 | L8: =CORREL(INDEX(rngData,0,4),INDEX(rngData,0,11)) -> 0.063281082 | M8: =CORREL(INDEX(rngData,0,4),INDEX(rngData,0,12)) -> 0.01364047
